<?xml version="1.0"?>
<!-- created with Phobos 1.0.1 "Capricious Choutengan" -->
<robot xmlns:xacro="http://wiki.ros.org/xacro">
  <xacro:macro name="rover_wheel" params="side pos parent_link xyz rpy wheel_material prefix">

    <xacro:if value="${side != 'left' and side != 'right'}">
      <xacro:error message="'side' parameter must be 'right' or 'left'."/>
    </xacro:if>

    <xacro:if value="${pos != 'front' and pos != 'mid' and pos != 'back'}">
      <xacro:error message="'pos' parameter must be 'front', 'mid' or 'back'."/>
    </xacro:if>

    <link name="${pos}_${side}_wheel_link">
      <collision name="${pos}_${side}_wheel_collision">
        <origin rpy="0.00000 -0.00000 -0.00000" xyz="-0.00000 -0.00000 -0.00000"/>
        <geometry>
          <mesh filename="package://speedy_description/meshes/dae/Torus.001.dae" scale="0.66102 0.66102 0.58333"/>
        </geometry>
        <surface>
          <friction>
            <ode>
              <mu>20.000000</mu>
              <mu2>20.000000</mu2>
              <fdir1>0.0000 0.0000 1.0000</fdir1>
              <slip1>0.50000</slip1>
              <slip2>0.50000</slip2>
            </ode>
          </friction>
        </surface>
      </collision>
      <inertial>
        <inertia ixx="0.08061" ixy="0.00000" ixz="-0.00000" iyy="0.12029" iyz="0.00000" izz="0.08061"/>
        <origin rpy="0.00000 0.00000 0.00000" xyz="-0.00000 -0.00000 -0.00000"/>
        <mass value="2.00000"/>
      </inertial>
      <visual name="${pos}_${side}_wheel">
        <origin rpy="0.00000 -0.00000 -0.00000" xyz="-0.00000 -0.00000 -0.00000"/>
        <material name="${wheel_material}"/>
        <geometry>
          <mesh filename="package://speedy_description/meshes/dae/Torus.001.dae" scale="0.66102 0.66102 0.58333"/>
        </geometry>
      </visual>
    </link>

    <joint name="${pos}_${side}_wheel_joint" type="continuous">
      <parent link="${parent_link}"/>
      <child link="${pos}_${side}_wheel_link"/>
      <origin xyz="${xyz}" rpy="${rpy}"/>
      <axis xyz="0.00000 0.00000 1.00000"/>
      <limit velocity="5.1282" effort="1000.0"/>
    </joint>

    <transmission name="${pos}_${side}_wheel_joint_trans">
      <type>transmission_interface/SimpleTransmission</type>
      <joint name="${pos}_${side}_wheel_joint">
        <hardwareInterface>hardware_interface/VelocityJointInterface</hardwareInterface>
      </joint>
      <actuator name="${pos}_${side}_wheel_joint_motor">
        <mechanicalReduction>1</mechanicalReduction>
      </actuator>
    </transmission>

    <gazebo reference="${pos}_${side}_wheel_link">
      <mu1>5</mu1>
      <mu2>5</mu2>
      <kp>2.72e6</kp>
      <kd>8.25e1</kd>
      <fdir1>0 0 0</fdir1>
      <maxContacts>4</maxContacts>
    </gazebo>

  </xacro:macro>

</robot>